root - ERROR - Error occurred
Traceback (most recent call last):
  File "d:\project_DIY\src\u1.py", line 24, in main
    pd.read_csv("da.csv")
  File "C:\Users\acer\AppData\Local\Programs\Python\Python310\lib\site-packages\pandas\io\parsers\readers.py", line 948, in read_csv
    return _read(filepath_or_buffer, kwds)
  File "C:\Users\acer\AppData\Local\Programs\Python\Python310\lib\site-packages\pandas\io\parsers\readers.py", line 611, in _read
    parser = TextFileReader(filepath_or_buffer, **kwds)
  File "C:\Users\acer\AppData\Local\Programs\Python\Python310\lib\site-packages\pandas\io\parsers\readers.py", line 1448, in __init__
    self._engine = self._make_engine(f, self.engine)
  File "C:\Users\acer\AppData\Local\Programs\Python\Python310\lib\site-packages\pandas\io\parsers\readers.py", line 1705, in _make_engine
    self.handles = get_handle(
  File "C:\Users\acer\AppData\Local\Programs\Python\Python310\lib\site-packages\pandas\io\common.py", line 863, in get_handle
    handle = open(
FileNotFoundError: [Errno 2] No such file or directory: 'da.csv'
